я правильно понял
1) Если я выброшу исключение, тогда я прерву поток и перейду к выполнению метода .doOnTerminate(() -> log.info("Запрос завершен."))  
2) Если я не буду выбрасывать исключение, то поток не прервется и в случае isError == true, я так же попаду в 
.doOnSuccess(response -> log.info("Запрос выполнен успешно: {}", response))  // Логируем успешное выполнение запроса.
    .bodyToMono(DepositResponse.class)  


ChatGPT сказал:
Не совсем так. Давайте разберем это поэтапно:

1) Если я выброшу исключение:
Если вы выбрасываете исключение в блоке onStatus, например, с помощью Mono.error(), то поток прерывается, и никакие дальнейшие обработчики (включая doOnSuccess) не выполняются. Исключение фактически завершит обработку и вызовет обработчик ошибок (если таковой имеется).

Пример с выбросом исключения:

java
Копировать
Редактировать
.onStatus(HttpStatus::isError, response ->  // Проверка на ошибку в ответе.
    response.bodyToMono(DepositErrorResponse.class)
        .flatMap(errorResponse -> Mono.error(new DepositException(errorResponse)))  // Поток прерывается здесь.
)
В случае ошибки, поток завершится с ошибкой и не дойдет до doOnSuccess, так как исключение прервет дальнейшую обработку.
В doOnTerminate всё равно попадете, потому что он срабатывает в любом случае (независимо от того, ошибка или успешный результат), но остальная логика запроса (например, успешная обработка в doOnSuccess) не будет выполнена.
2) Если я не выброшу исключение:
Если вы не выбрасываете исключение и вместо этого продолжаете поток, например, возвращаете объект с ошибкой или Mono.just(), то поток не прерывается, и выполнение продолжится в блоке doOnSuccess, если ответ будет считаться успешным (например, статус 2xx).

Пример без выброса исключения:

java
Копировать
Редактировать
.onStatus(HttpStatus::isError, response ->  // Проверка на ошибку в ответе.
    response.bodyToMono(DepositErrorResponse.class)
        .flatMap(errorResponse -> {
            log.info("Обработка ошибки: {}", errorResponse.getMessage());
            return Mono.just(new DepositResponse("Ошибка при обработке депозита"));  // Поток продолжится.
        })
)
В этом случае ошибка будет обработана, но поток продолжится.
Так как вы возвращаете объект DepositResponse, он будет передан в следующий блок, и doOnSuccess будет выполнен, потому что вы не завершаете поток с ошибкой.
Таким образом:

Если вы выбрасываете исключение, поток прерывается, и вы не попадете в doOnSuccess. Однако попадете в doOnTerminate.
Если вы не выбрасываете исключение, поток продолжится, и вы попадете в doOnSuccess, а также в doOnTerminate.
